<?xml version="1.0" ?>
<!-- =================================================================================== -->
<!-- |    This document was autogenerated by xacro from /workspaces/project/mr_ws/src/droid/urdf/droid.xacro | -->
<!-- |    EDITING THIS FILE BY HAND IS NOT RECOMMENDED                                 | -->
<!-- =================================================================================== -->
<robot name="droid">
    <material name="silver">
        <color rgba="0.700 0.700 0.700 1.000" />
    </material>
    <transmission name="Revolute_1_tran">
        <type>transmission_interface/SimpleTransmission</type>
        <joint name="Revolute_1">
            <hardwareInterface>hardware_interface/EffortJointInterface</hardwareInterface>
        </joint>
        <actuator name="Revolute_1_actr">
            <hardwareInterface>hardware_interface/EffortJointInterface</hardwareInterface>
            <mechanicalReduction>1</mechanicalReduction>
        </actuator>
    </transmission>
    <transmission name="Revolute_2_tran">
        <type>transmission_interface/SimpleTransmission</type>
        <joint name="Revolute_2">
            <hardwareInterface>hardware_interface/EffortJointInterface</hardwareInterface>
        </joint>
        <actuator name="Revolute_2_actr">
            <hardwareInterface>hardware_interface/EffortJointInterface</hardwareInterface>
            <mechanicalReduction>1</mechanicalReduction>
        </actuator>
    </transmission>
    <transmission name="Revolute_4_tran">
        <type>transmission_interface/SimpleTransmission</type>
        <joint name="Revolute_4">
            <hardwareInterface>hardware_interface/PositionJointInterface</hardwareInterface>
        </joint>
        <actuator name="Revolute_4_actr">
            <hardwareInterface>hardware_interface/PositionJointInterface</hardwareInterface>
            <mechanicalReduction>1</mechanicalReduction>
        </actuator>
    </transmission>
    <transmission name="Revolute_5_tran">
        <type>transmission_interface/SimpleTransmission</type>
        <joint name="Revolute_5">
            <hardwareInterface>hardware_interface/PositionJointInterface</hardwareInterface>
        </joint>
        <actuator name="Revolute_5_actr">
            <hardwareInterface>hardware_interface/PositionJointInterface</hardwareInterface>
            <mechanicalReduction>1</mechanicalReduction>
        </actuator>
    </transmission>
    <transmission name="Revolute_6_tran">
        <type>transmission_interface/SimpleTransmission</type>
        <joint name="Revolute_6">
            <hardwareInterface>hardware_interface/PositionJointInterface</hardwareInterface>
        </joint>
        <actuator name="Revolute_6_actr">
            <hardwareInterface>hardware_interface/PositionJointInterface</hardwareInterface>
            <mechanicalReduction>1</mechanicalReduction>
        </actuator>
    </transmission>
    <transmission name="Revolute_7_tran">
        <type>transmission_interface/SimpleTransmission</type>
        <joint name="Revolute_7">
            <hardwareInterface>hardware_interface/PositionJointInterface</hardwareInterface>
        </joint>
        <actuator name="Revolute_7_actr">
            <hardwareInterface>hardware_interface/PositionJointInterface</hardwareInterface>
            <mechanicalReduction>1</mechanicalReduction>
        </actuator>
    </transmission>
    <gazebo reference="base_link">
        <material>Gazebo/Silver</material>
        <mu1>0.2</mu1>
        <mu2>0.2</mu2>
        <self_collide>true</self_collide>
        <gravity>true</gravity>
        <plugin name="gazebo_ros_control" filename="libgazebo_ros_control.so">
            <robotNamespace>/</robotNamespace>
        </plugin>
    </gazebo>
    <gazebo reference="left_wheel_1">
        <material>Gazebo/Silver</material>
        <mu1>0.2</mu1>
        <mu2>0.2</mu2>
        <self_collide>true</self_collide>
    </gazebo>
    <gazebo reference="right_wheel_1">
        <material>Gazebo/Silver</material>
        <mu1>0.2</mu1>
        <mu2>0.2</mu2>
        <self_collide>true</self_collide>
    </gazebo>
    <gazebo reference="caster_1">
        <material>Gazebo/Silver</material>
        <mu1>0.2</mu1>
        <mu2>0.2</mu2>
        <self_collide>true</self_collide>
    </gazebo>
    <gazebo reference="link1_1">
        <material>Gazebo/Silver</material>
        <mu1>0.2</mu1>
        <mu2>0.2</mu2>
        <self_collide>true</self_collide>
    </gazebo>
    <gazebo reference="link2_1">
        <material>Gazebo/Silver</material>
        <mu1>0.2</mu1>
        <mu2>0.2</mu2>
        <self_collide>true</self_collide>
    </gazebo>
    <gazebo reference="link3_1">
        <material>Gazebo/Silver</material>
        <mu1>0.2</mu1>
        <mu2>0.2</mu2>
        <self_collide>true</self_collide>
    </gazebo>
    <gazebo reference="link4_1">
        <material>Gazebo/Silver</material>
        <mu1>0.2</mu1>
        <mu2>0.2</mu2>
        <self_collide>true</self_collide>
    </gazebo>
    <gazebo reference="battery_1">
        <material>Gazebo/Silver</material>
        <mu1>0.2</mu1>
        <mu2>0.2</mu2>
        <self_collide>true</self_collide>
    </gazebo>
    <gazebo reference="lidar_1">
        <material>Gazebo/Silver</material>
        <mu1>0.2</mu1>
        <mu2>0.2</mu2>
        <self_collide>true</self_collide>
    </gazebo>
    <gazebo>
        <plugin filename="libgazebo_ros_control.so" name="gazebo_ros_control">
            <robotNamespace>/</robotNamespace>
        </plugin>
    </gazebo>
    <gazebo>
        <plugin filename="libgazebo_ros_diff_drive.so" name="mr_diff_drive">
            <alwaysOn>true</alwaysOn>
            <commandTopic>cmd_vel</commandTopic>
            <odometryTopic>odom</odometryTopic>
            <odometryFrame>odom</odometryFrame>
            <odometrySource>world</odometrySource>
            <publishOdomTF>true</publishOdomTF>
            <robotBaseFrame>base_link</robotBaseFrame>
            <publishWheelTF>false</publishWheelTF>
            <publishTf>true</publishTf>
            <publishWheelJointState>true</publishWheelJointState>
            <legacyMode>false</legacyMode>
            <updateRate>10</updateRate>
            <leftJoint>Revolute_2</leftJoint>
            <rightJoint>Revolute_1</rightJoint>
            <wheelSeparation>0.489</wheelSeparation>
            <wheelDiameter>0.203</wheelDiameter>
            <wheelAcceleration>1</wheelAcceleration>
            <wheelTorque>200</wheelTorque>
            <rosDebugLevel>na</rosDebugLevel>
        </plugin>
    </gazebo>
    <gazebo>
        <sensor name="laser" type="ray">
            <pose>0 0 0 0 0 0</pose>
            <visualize>true</visualize>
            <update_rate>10</update_rate>
            <ray>
                <scan>
                    <horizontal>
                        <samples>360</samples>
                        <resolution>1</resolution>
                        <min_angle>-3.14</min_angle>
                        <max_angle>3.14</max_angle>
                    </horizontal>
                </scan>
                <range>
                    <min>0.3</min>
                    <max>12</max>
                    <resolution>0.001</resolution>
                </range>
                <noise>
                    <type>gaussian</type>
                    <mean>0.0</mean>
                    <stddev>0.0</stddev>
                </noise>
            </ray>
            <plugin filename="libgazebo_ros_ray_sensor.so" name="laser_controller">
                <ros>
                    <argument>~/out:=scan</argument>
                </ros>
                <output_type>sensor_msgs/LaserScan</output_type>
                <frame_name>laser_frame</frame_name>
            </plugin>
        </sensor>
    </gazebo>
    <link name="base_link">
        <inertial>
            <origin rpy="0 0 0" xyz="7.547718156495847e-05 -0.03807754440571188 0.4436980469756012" />
            <mass value="32.79273400746075" />
            <inertia ixx="5.034727" ixy="0.00047" ixz="0.002953" iyy="5.005009" iyz="-0.005055" izz="3.345194" />
        </inertial>
        <visual>
            <origin rpy="0 0 0" xyz="0 0 0" />
            <geometry>
                <mesh filename="file:///workspaces/project/mr_ws/src/droid/meshes/base_link.stl" scale="0.001 0.001 0.001" />
            </geometry>
            <material name="silver" />
        </visual>
        <collision>
            <origin rpy="0 0 0" xyz="0 0 0" />
            <geometry>
                <mesh filename="file:///workspaces/project/mr_ws/src/droid/meshes/base_link.stl" scale="0.001 0.001 0.001" />
            </geometry>
        </collision>
    </link>
    <link name="right_wheel_1">
        <inertial>
            <origin rpy="0 0 0" xyz="0.030529552152968376 1.9068881118577963e-07 -0.05000001188615662" />
            <mass value="0.9925749839884045" />
            <inertia ixx="0.006414" ixy="0.0" ixz="-0.0" iyy="0.003327" iyz="-0.0" izz="0.003327" />
        </inertial>
        <visual>
            <origin rpy="0 0 0" xyz="-0.195 0.183731 -0.104" />
            <geometry>
                <mesh filename="file:///workspaces/project/mr_ws/src/droid/meshes/right_wheel_1.stl" scale="0.001 0.001 0.001" />
            </geometry>
            <material name="silver" />
        </visual>
        <collision>
            <origin rpy="0 0 0" xyz="-0.195 0.183731 -0.104" />
            <geometry>
                <mesh filename="file:///workspaces/project/mr_ws/src/droid/meshes/right_wheel_1.stl" scale="0.001 0.001 0.001" />
            </geometry>
        </collision>
    </link>
    <link name="left_wheel_1">
        <inertial>
            <origin rpy="0 0 0" xyz="-0.03052955016277581 1.8838851645330834e-07 -0.05000001305090443" />
            <mass value="0.9925752931824147" />
            <inertia ixx="0.006414" ixy="-0.0" ixz="0.0" iyy="0.003327" iyz="0.0" izz="0.003327" />
        </inertial>
        <visual>
            <origin rpy="0 0 0" xyz="0.195 0.183731 -0.104" />
            <geometry>
                <mesh filename="file:///workspaces/project/mr_ws/src/droid/meshes/left_wheel_1.stl" scale="0.001 0.001 0.001" />
            </geometry>
            <material name="silver" />
        </visual>
        <collision>
            <origin rpy="0 0 0" xyz="0.195 0.183731 -0.104" />
            <geometry>
                <mesh filename="file:///workspaces/project/mr_ws/src/droid/meshes/left_wheel_1.stl" scale="0.001 0.001 0.001" />
            </geometry>
        </collision>
    </link>
    <link name="caster_1">
        <inertial>
            <origin rpy="0 0 0" xyz="3.023617962042337e-17 0.15949999999991615 -0.07052096677919327" />
            <mass value="0.07895916819270792" />
            <inertia ixx="3.4e-05" ixy="0.0" ixz="0.0" iyy="3.4e-05" iyz="-0.0" izz="4.3e-05" />
        </inertial>
        <visual>
            <origin rpy="0 0 0" xyz="0.0 -0.001 -0.1" />
            <geometry>
                <mesh filename="file:///workspaces/project/mr_ws/src/droid/meshes/caster_1.stl" scale="0.001 0.001 0.001" />
            </geometry>
            <material name="silver" />
        </visual>
        <collision>
            <origin rpy="0 0 0" xyz="0.0 -0.001 -0.1" />
            <geometry>
                <mesh filename="file:///workspaces/project/mr_ws/src/droid/meshes/caster_1.stl" scale="0.001 0.001 0.001" />
            </geometry>
        </collision>
    </link>
    <link name="link1_1">
        <inertial>
            <origin rpy="0 0 0" xyz="-0.06250850996368101 5.444018179756593e-06 -0.005474091051518637" />
            <mass value="1.2760077810090908" />
            <inertia ixx="0.001153" ixy="1e-06" ixz="0.000714" iyy="0.003912" iyz="-0.0" izz="0.004012" />
        </inertial>
        <visual>
            <origin rpy="0 0 0" xyz="0.125 0.2095 -0.895" />
            <geometry>
                <mesh filename="file:///workspaces/project/mr_ws/src/droid/meshes/link1_1.stl" scale="0.001 0.001 0.001" />
            </geometry>
            <material name="silver" />
        </visual>
        <collision>
            <origin rpy="0 0 0" xyz="0.125 0.2095 -0.895" />
            <geometry>
                <mesh filename="file:///workspaces/project/mr_ws/src/droid/meshes/link1_1.stl" scale="0.001 0.001 0.001" />
            </geometry>
        </collision>
    </link>
    <link name="link2_1">
        <inertial>
            <origin rpy="0 0 0" xyz="-0.010701828747098963 -4.4958367170777613e-07 0.1558180861055617" />
            <mass value="0.7433388099336727" />
            <inertia ixx="0.006714" ixy="-0.0" ixz="3.3e-05" iyy="0.006619" iyz="-0.0" izz="0.000152" />
        </inertial>
        <visual>
            <origin rpy="0 0 0" xyz="0.119 0.2095 -0.8985" />
            <geometry>
                <mesh filename="file:///workspaces/project/mr_ws/src/droid/meshes/link2_1.stl" scale="0.001 0.001 0.001" />
            </geometry>
            <material name="silver" />
        </visual>
        <collision>
            <origin rpy="0 0 0" xyz="0.119 0.2095 -0.8985" />
            <geometry>
                <mesh filename="file:///workspaces/project/mr_ws/src/droid/meshes/link2_1.stl" scale="0.001 0.001 0.001" />
            </geometry>
        </collision>
    </link>
    <link name="link3_1">
        <inertial>
            <origin rpy="0 0 0" xyz="0.021812589489625264 -0.1425308997121835 -2.53293049512493e-06" />
            <mass value="0.8685051191230937" />
            <inertia ixx="0.010207" ixy="-0.000494" ixz="-0.0" iyy="0.000299" iyz="0.0" izz="0.010243" />
        </inertial>
        <visual>
            <origin rpy="0 0 0" xyz="0.1281 0.2095 -1.1985" />
            <geometry>
                <mesh filename="file:///workspaces/project/mr_ws/src/droid/meshes/link3_1.stl" scale="0.001 0.001 0.001" />
            </geometry>
            <material name="silver" />
        </visual>
        <collision>
            <origin rpy="0 0 0" xyz="0.1281 0.2095 -1.1985" />
            <geometry>
                <mesh filename="file:///workspaces/project/mr_ws/src/droid/meshes/link3_1.stl" scale="0.001 0.001 0.001" />
            </geometry>
        </collision>
    </link>
    <link name="link4_1">
        <inertial>
            <origin rpy="0 0 0" xyz="-0.031249999999475267 -0.022812133439198745 6.424616394440363e-11" />
            <mass value="0.018644220362227914" />
            <inertia ixx="4e-06" ixy="0.0" ixz="0.0" iyy="1.4e-05" iyz="0.0" izz="1.5e-05" />
        </inertial>
        <visual>
            <origin rpy="0 0 0" xyz="0.0941 0.517 -1.1985" />
            <geometry>
                <mesh filename="file:///workspaces/project/mr_ws/src/droid/meshes/link4_1.stl" scale="0.001 0.001 0.001" />
            </geometry>
            <material name="silver" />
        </visual>
        <collision>
            <origin rpy="0 0 0" xyz="0.0941 0.517 -1.1985" />
            <geometry>
                <mesh filename="file:///workspaces/project/mr_ws/src/droid/meshes/link4_1.stl" scale="0.001 0.001 0.001" />
            </geometry>
        </collision>
    </link>
    <link name="battery_1">
        <inertial>
            <origin rpy="0 0 0" xyz="0.0 -0.07499999877550168 0.0" />
            <mass value="12.397766666666666" />
            <inertia ixx="0.029484" ixy="0.0" ixz="0.0" iyy="0.022608" iyz="0.0" izz="0.032289" />
        </inertial>
        <visual>
            <origin rpy="0 0 0" xyz="0.0 -0.1705 -0.122" />
            <geometry>
                <mesh filename="file:///workspaces/project/mr_ws/src/droid/meshes/battery_1.stl" scale="0.001 0.001 0.001" />
            </geometry>
            <material name="silver" />
        </visual>
        <collision>
            <origin rpy="0 0 0" xyz="0.0 -0.1705 -0.122" />
            <geometry>
                <mesh filename="file:///workspaces/project/mr_ws/src/droid/meshes/battery_1.stl" scale="0.001 0.001 0.001" />
            </geometry>
        </collision>
    </link>
    <link name="lidar_1">
        <inertial>
            <origin rpy="0 0 0" xyz="-0.02992109765878212 0.03330125870979983 -0.038599453521245164" />
            <mass value="0.09395274356562654" />
            <inertia ixx="2.4e-05" ixy="0.0" ixz="0.0" iyy="2.4e-05" iyz="-0.0" izz="3e-05" />
        </inertial>
        <visual>
            <origin rpy="0 0 0" xyz="-0.2745 0.309 -0.895" />
            <geometry>
                <mesh filename="file:///workspaces/project/mr_ws/src/droid/meshes/lidar_1.stl" scale="0.001 0.001 0.001" />
            </geometry>
            <material name="silver" />
        </visual>
        <collision>
            <origin rpy="0 0 0" xyz="-0.2745 0.309 -0.895" />
            <geometry>
                <mesh filename="file:///workspaces/project/mr_ws/src/droid/meshes/lidar_1.stl" scale="0.001 0.001 0.001" />
            </geometry>
        </collision>
    </link>
    <joint name="Revolute_1" type="continuous">
        <origin rpy="0 0 0" xyz="0.195 -0.183731 0.104" />
        <parent link="base_link" />
        <child link="right_wheel_1" />
        <axis xyz="-1.0 -0.0 0.0" />
    </joint>
    <joint name="Revolute_2" type="continuous">
        <origin rpy="0 0 0" xyz="-0.195 -0.183731 0.104" />
        <parent link="base_link" />
        <child link="left_wheel_1" />
        <axis xyz="-1.0 0.0 -0.0" />
    </joint>
    <joint name="Rigid_3" type="fixed">
        <origin rpy="0 0 0" xyz="0.0 0.001 0.1" />
        <parent link="base_link" />
        <child link="caster_1" />
    </joint>
    <joint name="Revolute_4" type="revolute">
        <origin rpy="0 0 0" xyz="-0.125 -0.2095 0.895" />
        <parent link="base_link" />
        <child link="link1_1" />
        <axis xyz="-0.0 -0.0 -1.0" />
        <limit effort="1000" lower="-1.570796" upper="1.570796" velocity="100" />
    </joint>
    <joint name="Revolute_5" type="revolute">
        <origin rpy="0 0 0" xyz="0.006 0.0 0.0035" />
        <parent link="link1_1" />
        <child link="link2_1" />
        <axis xyz="-1.0 -0.0 -0.0" />
        <limit effort="1000" lower="-1.308997" upper="0.436332" velocity="100" />
    </joint>
    <joint name="Revolute_6" type="revolute">
        <origin rpy="0 0 0" xyz="-0.0041 0.0 0.3" />
        <parent link="link2_1" />
        <child link="link3_1" />
        <axis xyz="-1.0 0.0 -0.0" />
        <limit effort="1000" lower="-1.047198" upper="1.570796" velocity="100" />
    </joint>
    <joint name="Revolute_7" type="revolute">
        <origin rpy="0 0 0" xyz="0.034 -0.3075 0.0" />
        <parent link="link3_1" />
        <child link="link4_1" />
        <axis xyz="-1.0 0.0 -0.0" />
        <limit effort="1000" lower="-1.22173" upper="1.22173" velocity="100" />
    </joint>
    <joint name="Rigid_8" type="fixed">
        <origin rpy="0 0 0" xyz="0.0 0.1705 0.122" />
        <parent link="base_link" />
        <child link="battery_1" />
    </joint>
    <joint name="Rigid_9" type="fixed">
        <origin rpy="0 0 0" xyz="0.2745 -0.309 0.895" />
        <parent link="base_link" />
        <child link="lidar_1" />
    </joint>
</robot>

