<?xml version="1.0" ?>
<robot name="droid" xmlns:xacro="http://www.ros.org/wiki/xacro">

<xacro:include filename="$(find droid)/urdf/materials.xacro" />
<xacro:include filename="$(find droid)/urdf/droid.trans" />
<xacro:include filename="$(find droid)/urdf/droid.gazebo" />

<!-- BASE_FOOTPRINT LINK -->

<joint name="base_footprint_joint" type="fixed">
    <parent link="base_link"/>
    <child link="base_footprint"/>
    <origin xyz="0 0 0" rpy="0 0 0"/>
</joint>

<link name="base_footprint">
</link>

<link name="base_link">
  <inertial>
    <origin xyz="7.547718156495847e-05 -0.03807754440571188 0.4436980469756012" rpy="0 0 0"/>
    <mass value="32.79273400746075"/>
    <inertia ixx="5.034727" iyy="5.005009" izz="3.345194" ixy="0.00047" iyz="-0.005055" ixz="0.002953"/>
  </inertial>
  <visual>
    <origin xyz="0 0 0" rpy="0 0 0"/>
    <geometry>
      <mesh filename="file://$(find droid)/meshes/base_link.stl" scale="0.001 0.001 0.001"/>
    </geometry>
    <material name="silver"/>
  </visual>
  <collision>
    <origin xyz="0 0 0" rpy="0 0 0"/>
    <geometry>
      <mesh filename="file://$(find droid)/meshes/base_link.stl" scale="0.001 0.001 0.001"/>
    </geometry>
  </collision>
</link>

<link name="right_wheel_1">
  <inertial>
    <origin xyz="0.030529552152968376 1.9068881118577963e-07 -0.05000001188615662" rpy="0 0 0"/>
    <mass value="0.9925749839884045"/>
    <inertia ixx="0.006414" iyy="0.003327" izz="0.003327" ixy="0.0" iyz="-0.0" ixz="-0.0"/>
  </inertial>
  <visual>
    <origin xyz="-0.195 0.183731 -0.104" rpy="0 0 0"/>
    <geometry>
      <mesh filename="file://$(find droid)/meshes/right_wheel_1.stl" scale="0.001 0.001 0.001"/>
    </geometry>
    <material name="silver"/>
  </visual>
  <collision>
    <origin xyz="-0.195 0.183731 -0.104" rpy="0 0 0"/>
    <geometry>
      <mesh filename="file://$(find droid)/meshes/right_wheel_1.stl" scale="0.001 0.001 0.001"/>
    </geometry>
  </collision>
</link>

<link name="left_wheel_1">
  <inertial>
    <origin xyz="-0.03052955016277581 1.8838851645330834e-07 -0.05000001305090443" rpy="0 0 0"/>
    <mass value="0.9925752931824147"/>
    <inertia ixx="0.006414" iyy="0.003327" izz="0.003327" ixy="-0.0" iyz="0.0" ixz="0.0"/>
  </inertial>
  <visual>
    <origin xyz="0.195 0.183731 -0.104" rpy="0 0 0"/>
    <geometry>
      <mesh filename="file://$(find droid)/meshes/left_wheel_1.stl" scale="0.001 0.001 0.001"/>
    </geometry>
    <material name="silver"/>
  </visual>
  <collision>
    <origin xyz="0.195 0.183731 -0.104" rpy="0 0 0"/>
    <geometry>
      <mesh filename="file://$(find droid)/meshes/left_wheel_1.stl" scale="0.001 0.001 0.001"/>
    </geometry>
  </collision>
</link>

<link name="caster_1">
  <inertial>
    <origin xyz="3.023617962042337e-17 0.15949999999991615 -0.07052096677919327" rpy="0 0 0"/>
    <mass value="0.07895916819270792"/>
    <inertia ixx="3.4e-05" iyy="3.4e-05" izz="4.3e-05" ixy="0.0" iyz="-0.0" ixz="0.0"/>
  </inertial>
  <visual>
    <origin xyz="0.0 -0.001 -0.1" rpy="0 0 0"/>
    <geometry>
      <mesh filename="file://$(find droid)/meshes/caster_1.stl" scale="0.001 0.001 0.001"/>
    </geometry>
    <material name="silver"/>
  </visual>
  <collision>
    <origin xyz="0.0 -0.001 -0.1" rpy="0 0 0"/>
    <geometry>
      <mesh filename="file://$(find droid)/meshes/caster_1.stl" scale="0.001 0.001 0.001"/>
    </geometry>
  </collision>
</link>

<link name="link1_1">
  <inertial>
    <origin xyz="-0.06250850996368101 5.444018179756593e-06 -0.005474091051518637" rpy="0 0 0"/>
    <mass value="1.2760077810090908"/>
    <inertia ixx="0.001153" iyy="0.003912" izz="0.004012" ixy="1e-06" iyz="-0.0" ixz="0.000714"/>
  </inertial>
  <visual>
    <origin xyz="0.125 0.2095 -0.895" rpy="0 0 0"/>
    <geometry>
      <mesh filename="file://$(find droid)/meshes/link1_1.stl" scale="0.001 0.001 0.001"/>
    </geometry>
    <material name="silver"/>
  </visual>
  <collision>
    <origin xyz="0.125 0.2095 -0.895" rpy="0 0 0"/>
    <geometry>
      <mesh filename="file://$(find droid)/meshes/link1_1.stl" scale="0.001 0.001 0.001"/>
    </geometry>
  </collision>
</link>

<link name="link2_1">
  <inertial>
    <origin xyz="-0.010701828747098963 -4.4958367170777613e-07 0.1558180861055617" rpy="0 0 0"/>
    <mass value="0.7433388099336727"/>
    <inertia ixx="0.006714" iyy="0.006619" izz="0.000152" ixy="-0.0" iyz="-0.0" ixz="3.3e-05"/>
  </inertial>
  <visual>
    <origin xyz="0.119 0.2095 -0.8985" rpy="0 0 0"/>
    <geometry>
      <mesh filename="file://$(find droid)/meshes/link2_1.stl" scale="0.001 0.001 0.001"/>
    </geometry>
    <material name="silver"/>
  </visual>
  <collision>
    <origin xyz="0.119 0.2095 -0.8985" rpy="0 0 0"/>
    <geometry>
      <mesh filename="file://$(find droid)/meshes/link2_1.stl" scale="0.001 0.001 0.001"/>
    </geometry>
  </collision>
</link>

<link name="link3_1">
  <inertial>
    <origin xyz="0.021812589489625264 -0.1425308997121835 -2.53293049512493e-06" rpy="0 0 0"/>
    <mass value="0.8685051191230937"/>
    <inertia ixx="0.010207" iyy="0.000299" izz="0.010243" ixy="-0.000494" iyz="0.0" ixz="-0.0"/>
  </inertial>
  <visual>
    <origin xyz="0.1281 0.2095 -1.1985" rpy="0 0 0"/>
    <geometry>
      <mesh filename="file://$(find droid)/meshes/link3_1.stl" scale="0.001 0.001 0.001"/>
    </geometry>
    <material name="silver"/>
  </visual>
  <collision>
    <origin xyz="0.1281 0.2095 -1.1985" rpy="0 0 0"/>
    <geometry>
      <mesh filename="file://$(find droid)/meshes/link3_1.stl" scale="0.001 0.001 0.001"/>
    </geometry>
  </collision>
</link>

<link name="link4_1">
  <inertial>
    <origin xyz="-0.031249999999475267 -0.022812133439198745 6.424616394440363e-11" rpy="0 0 0"/>
    <mass value="0.018644220362227914"/>
    <inertia ixx="4e-06" iyy="1.4e-05" izz="1.5e-05" ixy="0.0" iyz="0.0" ixz="0.0"/>
  </inertial>
  <visual>
    <origin xyz="0.0941 0.517 -1.1985" rpy="0 0 0"/>
    <geometry>
      <mesh filename="file://$(find droid)/meshes/link4_1.stl" scale="0.001 0.001 0.001"/>
    </geometry>
    <material name="silver"/>
  </visual>
  <collision>
    <origin xyz="0.0941 0.517 -1.1985" rpy="0 0 0"/>
    <geometry>
      <mesh filename="file://$(find droid)/meshes/link4_1.stl" scale="0.001 0.001 0.001"/>
    </geometry>
  </collision>
</link>

<link name="battery_1">
  <inertial>
    <origin xyz="0.0 -0.07499999877550168 0.0" rpy="0 0 0"/>
    <mass value="12.397766666666666"/>
    <inertia ixx="0.029484" iyy="0.022608" izz="0.032289" ixy="0.0" iyz="0.0" ixz="0.0"/>
  </inertial>
  <visual>
    <origin xyz="0.0 -0.1705 -0.122" rpy="0 0 0"/>
    <geometry>
      <mesh filename="file://$(find droid)/meshes/battery_1.stl" scale="0.001 0.001 0.001"/>
    </geometry>
    <material name="silver"/>
  </visual>
  <collision>
    <origin xyz="0.0 -0.1705 -0.122" rpy="0 0 0"/>
    <geometry>
      <mesh filename="file://$(find droid)/meshes/battery_1.stl" scale="0.001 0.001 0.001"/>
    </geometry>
  </collision>
</link>

<link name="lidar_1">
  <inertial>
    <origin xyz="-0.02992109765878212 0.03330125870979983 -0.038599453521245164" rpy="0 0 0"/>
    <mass value="0.09395274356562654"/>
    <inertia ixx="2.4e-05" iyy="2.4e-05" izz="3e-05" ixy="0.0" iyz="-0.0" ixz="0.0"/>
  </inertial>
  <visual>
    <origin xyz="-0.2745 0.309 -0.895" rpy="0 0 0"/>
    <geometry>
      <mesh filename="file://$(find droid)/meshes/lidar_1.stl" scale="0.001 0.001 0.001"/>
    </geometry>
    <material name="silver"/>
  </visual>
  <collision>
    <origin xyz="-0.2745 0.309 -0.895" rpy="0 0 0"/>
    <geometry>
      <mesh filename="file://$(find droid)/meshes/lidar_1.stl" scale="0.001 0.001 0.001"/>
    </geometry>
  </collision>
</link>

<joint name="Revolute_1" type="continuous">
  <origin xyz="0.195 -0.183731 0.104" rpy="0 0 0"/>
  <parent link="base_link"/>
  <child link="right_wheel_1"/>
  <axis xyz="-1.0 -0.0 0.0"/>
</joint>

<joint name="Revolute_2" type="continuous">
  <origin xyz="-0.195 -0.183731 0.104" rpy="0 0 0"/>
  <parent link="base_link"/>
  <child link="left_wheel_1"/>
  <axis xyz="-1.0 0.0 -0.0"/>
</joint>

<joint name="Rigid_3" type="fixed">
  <origin xyz="0.0 0.001 0.1" rpy="0 0 0"/>
  <parent link="base_link"/>
  <child link="caster_1"/>
</joint>

<joint name="Revolute_4" type="revolute">
  <origin xyz="-0.125 -0.2095 0.895" rpy="0 0 0"/>
  <parent link="base_link"/>
  <child link="link1_1"/>
  <axis xyz="-0.0 -0.0 -1.0"/>
  <limit upper="1.570796" lower="-1.570796" effort="1000" velocity="100"/>
</joint>

<joint name="Revolute_5" type="revolute">
  <origin xyz="0.006 0.0 0.0035" rpy="0 0 0"/>
  <parent link="link1_1"/>
  <child link="link2_1"/>
  <axis xyz="-1.0 -0.0 -0.0"/>
  <limit upper="0.436332" lower="-1.308997" effort="1000" velocity="100"/>
</joint>

<joint name="Revolute_6" type="revolute">
  <origin xyz="-0.0041 0.0 0.3" rpy="0 0 0"/>
  <parent link="link2_1"/>
  <child link="link3_1"/>
  <axis xyz="-1.0 0.0 -0.0"/>
  <limit upper="1.570796" lower="-1.047198" effort="1000" velocity="100"/>
</joint>

<joint name="Revolute_7" type="revolute">
  <origin xyz="0.034 -0.3075 0.0" rpy="0 0 0"/>
  <parent link="link3_1"/>
  <child link="link4_1"/>
  <axis xyz="-1.0 0.0 -0.0"/>
  <limit upper="1.22173" lower="-1.22173" effort="1000" velocity="100"/>
</joint>

<joint name="Rigid_8" type="fixed">
  <origin xyz="0.0 0.1705 0.122" rpy="0 0 0"/>
  <parent link="base_link"/>
  <child link="battery_1"/>
</joint>

<joint name="Rigid_9" type="fixed">
  <origin xyz="0.2745 -0.309 0.895" rpy="0 0 0"/>
  <parent link="base_link"/>
  <child link="lidar_1"/>
</joint>

</robot>
